[2021-01-25 16:57:57,933] {taskinstance.py:670} INFO - Dependencies all met for <TaskInstance: clean_data.clean_data_search_result_interaction 2021-01-25T16:57:17.466260+00:00 [queued]>
[2021-01-25 16:57:57,981] {taskinstance.py:670} INFO - Dependencies all met for <TaskInstance: clean_data.clean_data_search_result_interaction 2021-01-25T16:57:17.466260+00:00 [queued]>
[2021-01-25 16:57:57,982] {taskinstance.py:880} INFO - 
--------------------------------------------------------------------------------
[2021-01-25 16:57:57,983] {taskinstance.py:881} INFO - Starting attempt 1 of 2
[2021-01-25 16:57:57,984] {taskinstance.py:882} INFO - 
--------------------------------------------------------------------------------
[2021-01-25 16:57:58,077] {taskinstance.py:901} INFO - Executing <Task(PythonOperator): clean_data_search_result_interaction> on 2021-01-25T16:57:17.466260+00:00
[2021-01-25 16:57:58,081] {standard_task_runner.py:54} INFO - Started process 50873 to run task
[2021-01-25 16:57:58,118] {standard_task_runner.py:77} INFO - Running: ['airflow', 'run', 'clean_data', 'clean_data_search_result_interaction', '2021-01-25T16:57:17.466260+00:00', '--job_id', '29', '--pool', 'default_pool', '--raw', '-sd', 'DAGS_FOLDER/data_clean.py', '--cfg_path', '/tmp/tmpblknl9i7']
[2021-01-25 16:57:58,121] {standard_task_runner.py:78} INFO - Job 29: Subtask clean_data_search_result_interaction
[2021-01-25 16:57:58,205] {logging_mixin.py:112} INFO - Running %s on host %s <TaskInstance: clean_data.clean_data_search_result_interaction 2021-01-25T16:57:17.466260+00:00 [running]> 3f8da9634a9c
[2021-01-25 16:57:58,654] {taskinstance.py:1150} ERROR - 'search_ids'
Traceback (most recent call last):
  File "/home/airflow/.local/lib/python3.6/site-packages/pandas/core/indexes/base.py", line 2889, in get_loc
    return self._engine.get_loc(casted_key)
  File "pandas/_libs/index.pyx", line 70, in pandas._libs.index.IndexEngine.get_loc
  File "pandas/_libs/index.pyx", line 97, in pandas._libs.index.IndexEngine.get_loc
  File "pandas/_libs/hashtable_class_helper.pxi", line 1675, in pandas._libs.hashtable.PyObjectHashTable.get_item
  File "pandas/_libs/hashtable_class_helper.pxi", line 1683, in pandas._libs.hashtable.PyObjectHashTable.get_item
KeyError: 'search_ids'

The above exception was the direct cause of the following exception:

Traceback (most recent call last):
  File "/home/airflow/.local/lib/python3.6/site-packages/airflow/models/taskinstance.py", line 984, in _run_raw_task
    result = task_copy.execute(context=context)
  File "/home/airflow/.local/lib/python3.6/site-packages/airflow/operators/python_operator.py", line 113, in execute
    return_value = self.execute_callable()
  File "/home/airflow/.local/lib/python3.6/site-packages/airflow/operators/python_operator.py", line 118, in execute_callable
    return self.python_callable(*self.op_args, **self.op_kwargs)
  File "/opt/airflow/dags/data_clean.py", line 134, in clean_data_df
    search_request_ids = search_request_df['search_ids'].tolist()
  File "/home/airflow/.local/lib/python3.6/site-packages/pandas/core/frame.py", line 2899, in __getitem__
    indexer = self.columns.get_loc(key)
  File "/home/airflow/.local/lib/python3.6/site-packages/pandas/core/indexes/base.py", line 2891, in get_loc
    raise KeyError(key) from err
KeyError: 'search_ids'
[2021-01-25 16:57:58,680] {taskinstance.py:1194} INFO - Marking task as UP_FOR_RETRY. dag_id=clean_data, task_id=clean_data_search_result_interaction, execution_date=20210125T165717, start_date=20210125T165757, end_date=20210125T165758
[2021-01-25 16:58:02,888] {local_task_job.py:102} INFO - Task exited with return code 1
